Workbook

Sheet All Charters Unified
A1: Charter_Source Ticket # | B1: Charter Month | C1: Source_File | D1: NYSSIS ID | E1: Student ID | F1: Last Name | G1: First Name | H1: Grade Level | I1: DOB | J1: School Name | K1: Enroll Date | L1: Withdraw Date | M1: SCSD FTE | N1: Student Status | O1: Notes for Patrick | P1: SPED_Flag
A2: Southside 291462 | B2: 46174 | C2: southside_291462_unified-roster.xlsx | D2: 1630725543 | E2: 210010695 | F2: Thomas | G2: Aaleiyah | H2: 2 | I2: 43094 | J2: Southside Academy Charter School | K2: 45904 | M2: 1 | N2: No Good | O2: ST states: student enrolled at Southside Academy Charter School 8/2/255 - 9/1/25 . Entry date is 3> discrepancy. Need charter attendance record to change in ST. | P2: Gen Ed
A3: Southside 291462 | B3: 46174 | C3: southside_291462_unified-roster.xlsx | D3: 7417895120 | E3: 210022348 | F3: East | G3: Abel | H3: K | I3: 43993 | J3: Southside Academy Charter School | K3: 45903 | L3: 45940 | M3: 0.15 | N3: No Good | O3: ST states: student started Southside Academy Charter School 9/3/25 . Entry date is 3> discrepancy. Need charter attendance record to change in ST. | P3: Gen Ed
A4: Southside 291462 | B4: 46174 | C4: southside_291462_unified-roster.xlsx | D4: 6114934235 | E4: 200036757 | F4: Smith | G4: Adorre | H4: 4 | I4: 42225 | J4: Southside Academy Charter School | K4: 45904 | M4: 0.975 | N4: No Good | O4: ST states: student started McKiunley Brighton ES 4/8/26-current. Need charter attendance record to change in ST. | P4: SPED
A5: Southside 291462 | B5: 46174 | C5: southside_291462_unified-roster.xlsx | D5: 8894205962 | E5: 200032672 | F5: Maloof | G5: Aiden | H5: 8 | I5: 41220 | J5: Southside Academy Charter School | K5: 45903 | L5: 46077 | M5: 0.575 | N5: No Good | O5: ST states: Enrolled at Southside Academy 7/1/25-2/9/26. Enrolled at Lincoln MS 2/10/26-current. Exit date 3> discrepancy. Need charter attendance record to change in ST. | P5: Gen Ed
A6: Southside 291462 | B6: 46174 | C6: southside_291462_unified-roster.xlsx | D6: 9715356981 | E6: 210019407 | F6: McClain | G6: Ali | H6: K | I6: 44190 | J6: Southside Academy Charter School | K6: 45904 | M6: 0.975 | N6: No Good | O6: ST states: student enrolled at Southside Academy Charter 1/15/26-current. Entry date is 3> day discrepancy. Need charter attendance record to change in ST. | P6: Gen Ed
A7: Southside 291462 | B7: 46174 | C7: southside_291462_unified-roster.xlsx | D7: 7916282794 | E7: 210003054 | F7: Rufus | G7: Amir | H7: 4 | I7: 42677 | J7: Southside Academy Charter School | K7: 45909 | M7: 0.975 | N7: No Good | O7: ST states: student enrolled at Southside Academny 9/29/25. Entry date 3> day discrepancy. Need charter attendance record to change in ST. | P7: Gen Ed
A8: Southside 291462 | B8: 46174 | C8: southside_291462_unified-roster.xlsx | D8: 5016968523 | F8: Felder | G8: Anessa | H8: 1 | I8: 43675 | J8: Southside Academy Charter School | K8: 45904 | L8: 45917 | M8: 0.05 | N8: No Good | O8: ST states: No charter 25-26 enrollment in ST.Bellevue ES / ES enrollment 7/1/25 - 9/15/25. Enrolled at Van Duyn ES Van Duyn ES / ES - current. Need charter school attendance record to change in ST. | P8: Gen Ed
A9: Southside 291462 | B9: 46174 | C9: southside_291462_unified-roster.xlsx | D9: 1567036743 | E9: 210022223 | F9: Tindley | G9: Annalisse | H9: 2 | I9: 43334 | J9: Southside Academy Charter School | K9: 45915 | M9: 0.95 | N9: No Good | O9: ST states: student enrolled at Southside Academny 9/26/25. Entry date 3> day discrepancy. Need charter attendance record to change in ST. | P9: Gen Ed
A10: Southside 291462 | B10: 46174 | C10: southside_291462_unified-roster.xlsx | D10: 9622581930 | E10: 210014483 | F10: Dennis | G10: Arhianna | H10: 1 | I10: 43699 | J10: Southside Academy Charter School | K10: 45904 | L10: 45994 | M10: 0.3 | N10: No Good | O10: ST states: student enrolled at Southside Academy Charter School 8/16/25.25 11/25/25. Enrolled at HW Smith PK-8 12/1/25 - current. Entry date 3> day discrepancy. Need charter attendance record to change in ST. | P10: Gen Ed
A11: Southside 291462 | B11: 46174 | C11: southside_291462_unified-roster.xlsx | D11: 8381796603 | F11: Loper | G11: Bobby | H11: K | I11: 44194 | J11: Southside Academy Charter School | K11: 45903 | M11: 1 | N11: No Good | O11: ST states:No 25-26 charter shool enrollment entry in ST student enrolled at Bellevue ES 7/1/25-9/10/25. | P11: Gen Ed
A12: Southside 291462 | B12: 46174 | C12: southside_291462_unified-roster.xlsx | D12: 8993227873 | E12: 210019759 | F12: Reome | G12: Caylyn | H12: 1 | I12: 43543 | J12: Southside Academy Charter School | K12: 45903 | L12: 45915 | M12: 0.05 | N12: No Good | O12: ST states: student enrolled at Southside Academy 7/1/25 - 9/11/25. Exit date 3> day discrepancy. Need charter attendance record to change in ST. Enrolled at Syracuse Academy of Science Elementary at St James 9/12/25 | P12: Gen Ed
A13: Southside 291462 | B13: 46174 | C13: southside_291462_unified-roster.xlsx | D13: 5531469482 | E13: 210003314 | F13: Reome Jr. | G13: Christopher | H13: 3 | I13: 42876 | J13: Southside Academy Charter School | K13: 45903 | L13: 45915 | M13: 0.05 | N13: No Good | O13: ST states: student enrolled at Southside Academy 7/1/25 - 9/11/25. Exit date 3> day discrepancy. Need charter attendance record to change in ST. Enrolled at Syracuse Academy of Science Elementary at St James 9/12/25 | P13: Gen Ed
A14: Southside 291462 | B14: 46174 | C14: southside_291462_unified-roster.xlsx | D14: 7205350121 | E14: 210018482 | F14: Davis | G14: Cyh'Mora | H14: 1 | I14: 43826 | J14: Southside Academy Charter School | K14: 45903 | M14: 1 | N14: No Good | O14: ST states: student enrolled at Southside Academy Charter School9/25/25 - current. Entry date 3> day discrepancy. Need charter attendance record to change in ST. | P14: Gen Ed
A15: Southside 291462 | B15: 46174 | C15: southside_291462_unified-roster.xlsx | D15: 4427385530 | F15: 0 | G15: Donald | H15: K | I15: 44172 | J15: Southside Academy Charter School | K15: 45903 | M15: 1 | N15: Not in ST System | O15: Not pulling up in ST. Need more student information. NYSSIS ID, Last name,grade,parent info, gender, race, etc. | P15: Gen Ed
A16: Southside 291462 | B16: 46174 | C16: southside_291462_unified-roster.xlsx | D16: 5481567902 | E16: 210022691 | F16: Hatfield | G16: Draylan | H16: K | I16: 43853 | J16: Southside Academy Charter School | K16: 45905 | M16: 0.975 | N16: No Good | O16: ST states: student enrolled at Southside Academy Charter School 10/28/25 - current. Entry date 3> day discrepancy. Need charter attendance record to change in ST. | P16: SPED
A17: Southside 291462 | B17: 46174 | C17: southside_291462_unified-roster.xlsx | D17: 9345645621 | F17: 0 | G17: Edward | H17: K | I17: 43910 | J17: Southside Academy Charter School | K17: 45918 | M17: 0.925 | N17: Not in ST System | O17: Not pulling up in ST. Need more student information. NYSSIS ID, Last name,grade,parent info, gender, race, etc. | P17: Gen Ed
A18: Southside 291462 | B18: 46174 | C18: southside_291462_unified-roster.xlsx | D18: 3226816591 | E18: 210018247 | F18: Giddings | G18: Gracie | H18: K | I18: 44192 | J18: Southside Academy Charter School | K18: 45904 | M18: 0.975 | N18: No Good | O18: ST states: student enrolled at Southside Academy Charter School 1/7/25- current. Entry date 3> day discrepancy. Need charter attendance record to change in ST. | P18: Gen Ed
A19: Southside 291462 | B19: 46174 | C19: southside_291462_unified-roster.xlsx | D19: 8891043605 | E19: 210011263 | F19: Maldonado | G19: INessa | H19: 2 | I19: 43358 | J19: Southside Academy Charter School | K19: 45910 | M19: 0.975 | N19: No Good | O19: ST states: student enrolled at Southside Academy Charter School 11/5/25- current. Entry date 3> day discrepancy. Need charter attendance record to change in ST. | P19: SPED
A20: Southside 291462 | B20: 46174 | C20: southside_291462_unified-roster.xlsx | D20: 6207168494 | E20: 200038985 | F20: Sallard | G20: Jaliyah | H20: 4 | I20: 42561 | J20: Southside Academy Charter School | K20: 45915 | M20: 0.95 | N20: No Good | O20: ST states: student enrolled at Southside Academy Charter School 9/24/25- current. Entry date 3> day discrepancy. Need charter attendance record to change in ST. | P20: Gen Ed
A21: Southside 291462 | B21: 46174 | C21: southside_291462_unified-roster.xlsx | D21: 7360992380 | E21: 210022689 | F21: Vaughns | G21: Jayceon | H21: 2 | I21: 43318 | J21: Southside Academy Charter School | K21: 45905 | M21: 0.975 | N21: No Good | O21: ST states: student enrolled at Southside Academy Charter School 10/28/25- current. Entry date 3> day discrepancy. Need charter attendance record to change in ST. | P21: SPED
A22: Southside 291462 | B22: 46174 | C22: southside_291462_unified-roster.xlsx | D22: 9316354706 | E22: 210014757 | F22: Jackson | G22: Jordyn | H22: K | I22: 44128 | J22: Southside Academy Charter School | K22: 45903 | M22: 1 | N22: No Good | O22: ST states: student enrolled at Syracuse Academy of Science Elementary at St James 8/15/25 - 9/14/25. Enrolled at Southside Academy 9/15/25 - current. Entry 3> day discrepancy. Need charter attendance record to change in ST. | P22: Gen Ed
A23: Southside 291462 | B23: 46174 | C23: southside_291462_unified-roster.xlsx | F23: 0 | G23: Josiah | H23: 7 | I23: 41450 | J23: Southside Academy Charter School | K23: 45903 | M23: 1 | N23: Not in ST System | O23: Not pulling up in ST. | P23: Gen Ed
A24: Southside 291462 | B24: 46174 | C24: southside_291462_unified-roster.xlsx | D24: 4148681903 | E24: 210019004 | F24: Robertson | G24: Jovanni | H24: 1 | I24: 43725 | J24: Citizenship & Science Academy of Syracuse Charter | K24: 45903 | M24: 1 | N24: No Good | O24: ST states: student enrolled at Citizenship & Science Academy of Syracuse Charter 7/1/25 - 9/10/25.. Enrolled at Southside Academy 9/24/25 - current. Entry 3> day discrepancy. Need charter attendance record to change in ST. | P24: Gen Ed
A25: Southside 291462 | B25: 46174 | C25: southside_291462_unified-roster.xlsx | D25: 3321809294 | E25: 200033900 | F25: Anderson | G25: Juelez | H25: 5 | I25: 41625 | J25: Southside Academy Charter School | K25: 45903 | L25: 45995 | M25: 0.325 | N25: No Good | O25: ST states: student enrolled at Southside Academy Charter School 7/1/25- 11/24/25. Enrolled at STEAM @ Dr King / ES 11/25/25- current. Entry date 3> day discrepancy. Need charter attendance record to change in ST. | P25: SPED
A26: Southside 291462 | B26: 46174 | C26: southside_291462_unified-roster.xlsx | D26: 2807672461 | E26: 200024256 | F26: Cenzalli JR | G26: Justin | H26: 8 | I26: 41042 | J26: Southside Academy Charter School | K26: 45903 | L26: 45919 | M26: 0.075 | N26: No Good | O26: ST states: student enrolled at Southside Academy Charter School 9/6/25 - 9/11/25. Enrolled at Ed Smith PK-8 / MS 9/18/25- 2/6/25. Entry date 3> day discrepancy. Need charter attendance record to change in ST. | P26: SPED
A27: Southside 291462 | B27: 46174 | C27: southside_291462_unified-roster.xlsx | D27: 3908940154 | E27: 210002244 | F27: Lobban | G27: Kahwi | H27: 5 | I27: 41841 | J27: Southside Academy Charter School | K27: 45904 | L27: 45923 | M27: 0.05 | N27: No Good | O27: ST states: student enrolled at Southside Academy Charter School 7/1/25 - 9/8/25. Enrolled at STEAM @ Dr King / ES 9/18/25 - current. Entry date 3> day discrepancy. Need charter attendance record to change in ST. | P27: SPED
A28: Southside 291462 | B28: 46174 | C28: southside_291462_unified-roster.xlsx | D28: 4658757613 | F28: Titus | G28: Kaiden | H28: K | I28: 44196 | J28: Southside Academy Charter School | K28: 45903 | M28: 1 | N28: No Good | O28: ST states: enrolled at McKinley Brighton ES 7/3/25-9/8/25. With note that parent reported child will attend Southside. Need charter attendance report to change in ST. | P28: Gen Ed
A29: Southside 291462 | B29: 46174 | C29: southside_291462_unified-roster.xlsx | D29: 2808195416 | E29: 210017791 | F29: Maddox | G29: Kelani | H29: K | I29: 44152 | J29: Southside Academy Charter School | K29: 45917 | M29: 0.95 | N29: No Good | O29: ST states: student enrolled at Southside Academy Charter School 11/12/25- current. Entry date 3> day discrepancy. Need charter attendance record to change in ST. | P29: Gen Ed
A30: Southside 291462 | B30: 46174 | C30: southside_291462_unified-roster.xlsx | D30: 8014067546 | E30: 210022082 | F30: Suressi | G30: Kilani | H30: K | I30: 43979 | J30: Southside Academy Charter School | K30: 45905 | L30: 46010 | M30: 0.35 | N30: No Good | O30: ST states: student enrolled at Southside Academy Charter School 12/10/2025 - 12/21/2025. Entry date 3> day discrepancy. Need charter attendance record to change in ST. | P30: Gen Ed
A31: Southside 291462 | B31: 46174 | C31: southside_291462_unified-roster.xlsx | F31: 0 | G31: Kisean | H31: 0 | J31: Southside Academy Charter School | K31: 46097 | M31: 0.35 | N31: Not in ST System | O31: Not pulling up in ST. Need more student information. NYSSIS ID, Last name,grade,parent info, gender, race, etc. | P31: Gen Ed
A32: Southside 291462 | B32: 46174 | C32: southside_291462_unified-roster.xlsx | D32: 8110682342 | E32: 210006494 | F32: Matthews | G32: LaMonte | H32: 2 | I32: 43322 | J32: Southside Academy Charter School | K32: 45903 | L32: 46079 | M32: 0.6 | N32: No Good | O32: ST states: student enrolled at Southside Academy Charter School 8/25/2025 - 2/18/2026. Enrolled at Van Duyn ES / ES 2/19/26- current Entry date 3> day discrepancy. Need charter attendance record to change in ST. | P32: SPED
A33: Southside 291462 | B33: 46174 | C33: southside_291462_unified-roster.xlsx | D33: 2125386561 | F33: Brynien | G33: Liliana | H33: 4 | I33: 42384 | J33: Southside Academy Charter School | K33: 45964 | M33: 0.8 | N33: No Good | O33: No 25-26 enrollment in ST. Need charter attendance record to make change in ST. | P33: Gen Ed
A34: Southside 291462 | B34: 46174 | C34: southside_291462_unified-roster.xlsx | D34: 5279781642 | E34: 210017699 | F34: James-Haygood | G34: Llmanuel | H34: K | I34: 44110 | J34: Southside Academy Charter School | K34: 45908 | M34: 0.975 | N34: No Good | O34: ST states: Enrolled at Southside Academy Charter School 7/1/25 - 3/3/26. Need charter school attendance record to change in ST. | P34: Gen Ed
A35: Southside 291462 | B35: 46174 | C35: southside_291462_unified-roster.xlsx | D35: 6748943165 | E35: 210016382 | F35: Warde | G35: Malachi | H35: 6 | I35: 41501 | J35: Southside Academy Charter School | K35: 45903 | M35: 1 | N35: No Good | O35: ST states: student enrolled at Grant MS / MS 7/1/25 - 9/15/25. Enrolled at Southside Academy Charter School 9/16/25 - current. Entry date 3> day discrepancy. Need charter attendance record to change in ST. | P35: Gen Ed
A36: Southside 291462 | B36: 46174 | C36: southside_291462_unified-roster.xlsx | D36: 4302512531 | E36: 210002246 | F36: Lobban | G36: Mehki | H36: 5 | I36: 41841 | J36: Southside Academy Charter School | K36: 45904 | L36: 45919 | M36: 0.05 | N36: No Good | O36: ST states: student enrolled at Southside Academy Charter School 7/1/2025 - 9/8/2025. Enrolled at STEAM @ Dr King / ES 9/18/25 - current. Entry date 3> day discrepancy. Need charter attendance record to change in ST. | P36: SPED
A37: Southside 291462 | B37: 46174 | C37: southside_291462_unified-roster.xlsx | D37: 8460982760 | E37: 210022815 | F37: Lindsey | G37: Nadir | H37: K | I37: 44033 | J37: Southside Academy Charter School | K37: 45964 | L37: 46010 | M37: 0.175 | N37: No Good | O37: ST states: Enrolled at Southside Academy Charter School 11/12/25-current. Entry date 3> day discrepancy. Need charter school attendance record to change in ST. | P37: Gen Ed
A38: Southside 291462 | B38: 46174 | C38: southside_291462_unified-roster.xlsx | D38: 2981769541 | E38: 210009975 | F38: Smith | G38: Natalia | H38: 1 | I38: 43468 | J38: Southside Academy Charter School | K38: 45968 | M38: 0.775 | N38: No Good | O38: ST states: student enrolled at Southside Academy Charter School 12/10/2025 - current. Entry date 3> day discrepancy. Need charter attendance record to change in ST. | P38: Gen Ed
A39: Southside 291462 | B39: 46174 | C39: southside_291462_unified-roster.xlsx | D39: 6994835771 | F39: Morris | G39: Rahmier | H39: K | I39: 44148 | J39: Southside Academy Charter School | K39: 45903 | L39: 45923 | M39: 0.075 | N39: No Good | O39: No enrollment record in ST. Need charter school attendance to create enrollment entry in ST. | P39: Gen Ed
A40: Southside 291462 | B40: 46174 | C40: southside_291462_unified-roster.xlsx | D40: 1565701023 | E40: 210022225 | F40: Tarrats | G40: Ruben | H40: 7 | I40: 41464 | J40: Southside Academy Charter School | K40: 45915 | M40: 0.95 | N40: No Good | O40: ST states: student enrolled at Southside Academy Charter School 10/15/2025 - current. Entry date 3> day discrepancy. Need charter attendance record to change in ST. | P40: Gen Ed
...

Sheet Formula Version
A1: Charter_Source Ticket # | B1: Charter Month | C1: Source_File | D1: NYSSIS ID | E1: Student ID | F1: Last Name | G1: First Name | H1: Grade Level | I1: DOB | J1: School Name | K1: Enroll Date | L1: Withdraw Date | M1: SCSD FTE | N1: Student Status | O1: Notes for Patrick | P1: SPED_Flag | Q1: ST_NYSSIS_Lookup | R1: ST_School_Lookup | S1: ST_SID_Lookup | T1: Match_Source | U1: SPED_Disability_Lookup
A2: Southside 291462 | B2: 46174 | C2: southside_291462_unified-roster.xlsx | D2: 1630725543 | E2: 210010695 | F2: Thomas | G2: Aaleiyah | H2: 2 | I2: 43094 | J2: Southside Academy Charter School | K2: 45904 | M2: 1 | N2: No Good | O2: ST states: student enrolled at Southside Academy Charter School 8/2/255 - 9/1/25 . Entry date is 3> discrepancy. Need charter attendance record to change in ST. | P2: Gen Ed | Q2: =IFERROR(INDEX('ST Enroll Export'!$A$2:$A$3230,MATCH($D2,'ST Enroll Export'!$A$2:$A$3230,0)),IFERROR(IF(INDEX('ST Enroll Export'!$A$2:$A$3230,MATCH($E2,'ST Enroll Export'!$B$2:$B$3230,0))="","",INDEX('ST Enroll Export'!$A$2:$A$3230,MATCH($E2,'ST Enroll Export'!$B$2:$B$3230,0))),"Not Found")) -> 1630725543 | R2: =IFERROR(INDEX('ST Enroll Export'!$G$2:$G$3230,MATCH($D2,'ST Enroll Export'!$A$2:$A$3230,0)),IFERROR(INDEX('ST Enroll Export'!$G$2:$G$3230,MATCH($E2,'ST Enroll Export'!$B$2:$B$3230,0)),"Not Found")) -> Southside Academy Charter School | S2: =IFERROR(INDEX('ST Enroll Export'!$B$2:$B$3230,MATCH($D2,'ST Enroll Export'!$A$2:$A$3230,0)),IFERROR(INDEX('ST Enroll Export'!$B$2:$B$3230,MATCH($E2,'ST Enroll Export'!$B$2:$B$3230,0)),"Not Found")) -> 210010695 | T2: =IF(ISNUMBER(MATCH($D2,'ST Enroll Export'!$A$2:$A$3230,0)),"NYSSIS Match",IF(ISNUMBER(MATCH($E2,'ST Enroll Export'!$B$2:$B$3230,0)),"SID Match","No ST Match")) -> NYSSIS Match | U2: =IF(ISNUMBER(MATCH($D2,Disability!$B$2:$B$5962,0)),"SPED","Gen Ed") -> Gen Ed
A3: Southside 291462 | B3: 46174 | C3: southside_291462_unified-roster.xlsx | D3: 7417895120 | E3: 210022348 | F3: East | G3: Abel | H3: K | I3: 43993 | J3: Southside Academy Charter School | K3: 45903 | L3: 45940 | M3: 0.15 | N3: No Good | O3: ST states: student started Southside Academy Charter School 9/3/25 . Entry date is 3> discrepancy. Need charter attendance record to change in ST. | P3: Gen Ed | Q3: =IFERROR(INDEX('ST Enroll Export'!$A$2:$A$3230,MATCH($D3,'ST Enroll Export'!$A$2:$A$3230,0)),IFERROR(IF(INDEX('ST Enroll Export'!$A$2:$A$3230,MATCH($E3,'ST Enroll Export'!$B$2:$B$3230,0))="","",INDEX('ST Enroll Export'!$A$2:$A$3230,MATCH($E3,'ST Enroll Export'!$B$2:$B$3230,0))),"Not Found")) | R3: =IFERROR(INDEX('ST Enroll Export'!$G$2:$G$3230,MATCH($D3,'ST Enroll Export'!$A$2:$A$3230,0)),IFERROR(INDEX('ST Enroll Export'!$G$2:$G$3230,MATCH($E3,'ST Enroll Export'!$B$2:$B$3230,0)),"Not Found")) -> Southside Academy Charter School | S3: =IFERROR(INDEX('ST Enroll Export'!$B$2:$B$3230,MATCH($D3,'ST Enroll Export'!$A$2:$A$3230,0)),IFERROR(INDEX('ST Enroll Export'!$B$2:$B$3230,MATCH($E3,'ST Enroll Export'!$B$2:$B$3230,0)),"Not Found")) -> 210022348 | T3: =IF(ISNUMBER(MATCH($D3,'ST Enroll Export'!$A$2:$A$3230,0)),"NYSSIS Match",IF(ISNUMBER(MATCH($E3,'ST Enroll Export'!$B$2:$B$3230,0)),"SID Match","No ST Match")) -> SID Match | U3: =IF(ISNUMBER(MATCH($D3,Disability!$B$2:$B$5962,0)),"SPED","Gen Ed") -> Gen Ed
A4: Southside 291462 | B4: 46174 | C4: southside_291462_unified-roster.xlsx | D4: 6114934235 | E4: 200036757 | F4: Smith | G4: Adorre | H4: 4 | I4: 42225 | J4: Southside Academy Charter School | K4: 45904 | M4: 0.975 | N4: No Good | O4: ST states: student started McKiunley Brighton ES 4/8/26-current. Need charter attendance record to change in ST. | P4: SPED | Q4: =IFERROR(INDEX('ST Enroll Export'!$A$2:$A$3230,MATCH($D4,'ST Enroll Export'!$A$2:$A$3230,0)),IFERROR(IF(INDEX('ST Enroll Export'!$A$2:$A$3230,MATCH($E4,'ST Enroll Export'!$B$2:$B$3230,0))="","",INDEX('ST Enroll Export'!$A$2:$A$3230,MATCH($E4,'ST Enroll Export'!$B$2:$B$3230,0))),"Not Found")) -> 6114934235 | R4: =IFERROR(INDEX('ST Enroll Export'!$G$2:$G$3230,MATCH($D4,'ST Enroll Export'!$A$2:$A$3230,0)),IFERROR(INDEX('ST Enroll Export'!$G$2:$G$3230,MATCH($E4,'ST Enroll Export'!$B$2:$B$3230,0)),"Not Found")) -> Southside Academy Charter School | S4: =IFERROR(INDEX('ST Enroll Export'!$B$2:$B$3230,MATCH($D4,'ST Enroll Export'!$A$2:$A$3230,0)),IFERROR(INDEX('ST Enroll Export'!$B$2:$B$3230,MATCH($E4,'ST Enroll Export'!$B$2:$B$3230,0)),"Not Found")) -> 200036757 | T4: =IF(ISNUMBER(MATCH($D4,'ST Enroll Export'!$A$2:$A$3230,0)),"NYSSIS Match",IF(ISNUMBER(MATCH($E4,'ST Enroll Export'!$B$2:$B$3230,0)),"SID Match","No ST Match")) -> NYSSIS Match | U4: =IF(ISNUMBER(MATCH($D4,Disability!$B$2:$B$5962,0)),"SPED","Gen Ed") -> SPED
A5: Southside 291462 | B5: 46174 | C5: southside_291462_unified-roster.xlsx | D5: 8894205962 | E5: 200032672 | F5: Maloof | G5: Aiden | H5: 8 | I5: 41220 | J5: Southside Academy Charter School | K5: 45903 | L5: 46077 | M5: 0.575 | N5: No Good | O5: ST states: Enrolled at Southside Academy 7/1/25-2/9/26. Enrolled at Lincoln MS 2/10/26-current. Exit date 3> discrepancy. Need charter attendance record to change in ST. | P5: Gen Ed | Q5: =IFERROR(INDEX('ST Enroll Export'!$A$2:$A$3230,MATCH($D5,'ST Enroll Export'!$A$2:$A$3230,0)),IFERROR(IF(INDEX('ST Enroll Export'!$A$2:$A$3230,MATCH($E5,'ST Enroll Export'!$B$2:$B$3230,0))="","",INDEX('ST Enroll Export'!$A$2:$A$3230,MATCH($E5,'ST Enroll Export'!$B$2:$B$3230,0))),"Not Found")) -> 8894205962 | R5: =IFERROR(INDEX('ST Enroll Export'!$G$2:$G$3230,MATCH($D5,'ST Enroll Export'!$A$2:$A$3230,0)),IFERROR(INDEX('ST Enroll Export'!$G$2:$G$3230,MATCH($E5,'ST Enroll Export'!$B$2:$B$3230,0)),"Not Found")) -> Southside Academy Charter School | S5: =IFERROR(INDEX('ST Enroll Export'!$B$2:$B$3230,MATCH($D5,'ST Enroll Export'!$A$2:$A$3230,0)),IFERROR(INDEX('ST Enroll Export'!$B$2:$B$3230,MATCH($E5,'ST Enroll Export'!$B$2:$B$3230,0)),"Not Found")) -> 200032672 | T5: =IF(ISNUMBER(MATCH($D5,'ST Enroll Export'!$A$2:$A$3230,0)),"NYSSIS Match",IF(ISNUMBER(MATCH($E5,'ST Enroll Export'!$B$2:$B$3230,0)),"SID Match","No ST Match")) -> NYSSIS Match | U5: =IF(ISNUMBER(MATCH($D5,Disability!$B$2:$B$5962,0)),"SPED","Gen Ed") -> SPED
A6: Southside 291462 | B6: 46174 | C6: southside_291462_unified-roster.xlsx | D6: 9715356981 | E6: 210019407 | F6: McClain | G6: Ali | H6: K | I6: 44190 | J6: Southside Academy Charter School | K6: 45904 | M6: 0.975 | N6: No Good | O6: ST states: student enrolled at Southside Academy Charter 1/15/26-current. Entry date is 3> day discrepancy. Need charter attendance record to change in ST. | P6: Gen Ed | Q6: =IFERROR(INDEX('ST Enroll Export'!$A$2:$A$3230,MATCH($D6,'ST Enroll Export'!$A$2:$A$3230,0)),IFERROR(IF(INDEX('ST Enroll Export'!$A$2:$A$3230,MATCH($E6,'ST Enroll Export'!$B$2:$B$3230,0))="","",INDEX('ST Enroll Export'!$A$2:$A$3230,MATCH($E6,'ST Enroll Export'!$B$2:$B$3230,0))),"Not Found")) -> 9715356981 | R6: =IFERROR(INDEX('ST Enroll Export'!$G$2:$G$3230,MATCH($D6,'ST Enroll Export'!$A$2:$A$3230,0)),IFERROR(INDEX('ST Enroll Export'!$G$2:$G$3230,MATCH($E6,'ST Enroll Export'!$B$2:$B$3230,0)),"Not Found")) -> Southside Academy Charter School | S6: =IFERROR(INDEX('ST Enroll Export'!$B$2:$B$3230,MATCH($D6,'ST Enroll Export'!$A$2:$A$3230,0)),IFERROR(INDEX('ST Enroll Export'!$B$2:$B$3230,MATCH($E6,'ST Enroll Export'!$B$2:$B$3230,0)),"Not Found")) -> 210019407 | T6: =IF(ISNUMBER(MATCH($D6,'ST Enroll Export'!$A$2:$A$3230,0)),"NYSSIS Match",IF(ISNUMBER(MATCH($E6,'ST Enroll Export'!$B$2:$B$3230,0)),"SID Match","No ST Match")) -> NYSSIS Match | U6: =IF(ISNUMBER(MATCH($D6,Disability!$B$2:$B$5962,0)),"SPED","Gen Ed") -> Gen Ed
A7: Southside 291462 | B7: 46174 | C7: southside_291462_unified-roster.xlsx | D7: 7916282794 | E7: 210003054 | F7: Rufus | G7: Amir | H7: 4 | I7: 42677 | J7: Southside Academy Charter School | K7: 45909 | M7: 0.975 | N7: No Good | O7: ST states: student enrolled at Southside Academny 9/29/25. Entry date 3> day discrepancy. Need charter attendance record to change in ST. | P7: Gen Ed | Q7: =IFERROR(INDEX('ST Enroll Export'!$A$2:$A$3230,MATCH($D7,'ST Enroll Export'!$A$2:$A$3230,0)),IFERROR(IF(INDEX('ST Enroll Export'!$A$2:$A$3230,MATCH($E7,'ST Enroll Export'!$B$2:$B$3230,0))="","",INDEX('ST Enroll Export'!$A$2:$A$3230,MATCH($E7,'ST Enroll Export'!$B$2:$B$3230,0))),"Not Found")) -> 7916282794 | R7: =IFERROR(INDEX('ST Enroll Export'!$G$2:$G$3230,MATCH($D7,'ST Enroll Export'!$A$2:$A$3230,0)),IFERROR(INDEX('ST Enroll Export'!$G$2:$G$3230,MATCH($E7,'ST Enroll Export'!$B$2:$B$3230,0)),"Not Found")) -> Southside Academy Charter School | S7: =IFERROR(INDEX('ST Enroll Export'!$B$2:$B$3230,MATCH($D7,'ST Enroll Export'!$A$2:$A$3230,0)),IFERROR(INDEX('ST Enroll Export'!$B$2:$B$3230,MATCH($E7,'ST Enroll Export'!$B$2:$B$3230,0)),"Not Found")) -> 210003054 | T7: =IF(ISNUMBER(MATCH($D7,'ST Enroll Export'!$A$2:$A$3230,0)),"NYSSIS Match",IF(ISNUMBER(MATCH($E7,'ST Enroll Export'!$B$2:$B$3230,0)),"SID Match","No ST Match")) -> NYSSIS Match | U7: =IF(ISNUMBER(MATCH($D7,Disability!$B$2:$B$5962,0)),"SPED","Gen Ed") -> Gen Ed
A8: Southside 291462 | B8: 46174 | C8: southside_291462_unified-roster.xlsx | D8: 5016968523 | F8: Felder | G8: Anessa | H8: 1 | I8: 43675 | J8: Southside Academy Charter School | K8: 45904 | L8: 45917 | M8: 0.05 | N8: No Good | O8: ST states: No charter 25-26 enrollment in ST.Bellevue ES / ES enrollment 7/1/25 - 9/15/25. Enrolled at Van Duyn ES Van Duyn ES / ES - current. Need charter school attendance record to change in ST. | P8: Gen Ed | Q8: =IFERROR(INDEX('ST Enroll Export'!$A$2:$A$3230,MATCH($D8,'ST Enroll Export'!$A$2:$A$3230,0)),IFERROR(IF(INDEX('ST Enroll Export'!$A$2:$A$3230,MATCH($E8,'ST Enroll Export'!$B$2:$B$3230,0))="","",INDEX('ST Enroll Export'!$A$2:$A$3230,MATCH($E8,'ST Enroll Export'!$B$2:$B$3230,0))),"Not Found")) -> Not Found | R8: =IFERROR(INDEX('ST Enroll Export'!$G$2:$G$3230,MATCH($D8,'ST Enroll Export'!$A$2:$A$3230,0)),IFERROR(INDEX('ST Enroll Export'!$G$2:$G$3230,MATCH($E8,'ST Enroll Export'!$B$2:$B$3230,0)),"Not Found")) -> Not Found | S8: =IFERROR(INDEX('ST Enroll Export'!$B$2:$B$3230,MATCH($D8,'ST Enroll Export'!$A$2:$A$3230,0)),IFERROR(INDEX('ST Enroll Export'!$B$2:$B$3230,MATCH($E8,'ST Enroll Export'!$B$2:$B$3230,0)),"Not Found")) -> Not Found | T8: =IF(ISNUMBER(MATCH($D8,'ST Enroll Export'!$A$2:$A$3230,0)),"NYSSIS Match",IF(ISNUMBER(MATCH($E8,'ST Enroll Export'!$B$2:$B$3230,0)),"SID Match","No ST Match")) -> No ST Match | U8: =IF(ISNUMBER(MATCH($D8,Disability!$B$2:$B$5962,0)),"SPED","Gen Ed") -> Gen Ed
A9: Southside 291462 | B9: 46174 | C9: southside_291462_unified-roster.xlsx | D9: 1567036743 | E9: 210022223 | F9: Tindley | G9: Annalisse | H9: 2 | I9: 43334 | J9: Southside Academy Charter School | K9: 45915 | M9: 0.95 | N9: No Good | O9: ST states: student enrolled at Southside Academny 9/26/25. Entry date 3> day discrepancy. Need charter attendance record to change in ST. | P9: Gen Ed | Q9: =IFERROR(INDEX('ST Enroll Export'!$A$2:$A$3230,MATCH($D9,'ST Enroll Export'!$A$2:$A$3230,0)),IFERROR(IF(INDEX('ST Enroll Export'!$A$2:$A$3230,MATCH($E9,'ST Enroll Export'!$B$2:$B$3230,0))="","",INDEX('ST Enroll Export'!$A$2:$A$3230,MATCH($E9,'ST Enroll Export'!$B$2:$B$3230,0))),"Not Found")) -> 1567036743 | R9: =IFERROR(INDEX('ST Enroll Export'!$G$2:$G$3230,MATCH($D9,'ST Enroll Export'!$A$2:$A$3230,0)),IFERROR(INDEX('ST Enroll Export'!$G$2:$G$3230,MATCH($E9,'ST Enroll Export'!$B$2:$B$3230,0)),"Not Found")) -> Southside Academy Charter School | S9: =IFERROR(INDEX('ST Enroll Export'!$B$2:$B$3230,MATCH($D9,'ST Enroll Export'!$A$2:$A$3230,0)),IFERROR(INDEX('ST Enroll Export'!$B$2:$B$3230,MATCH($E9,'ST Enroll Export'!$B$2:$B$3230,0)),"Not Found")) -> 210022223 | T9: =IF(ISNUMBER(MATCH($D9,'ST Enroll Export'!$A$2:$A$3230,0)),"NYSSIS Match",IF(ISNUMBER(MATCH($E9,'ST Enroll Export'!$B$2:$B$3230,0)),"SID Match","No ST Match")) -> NYSSIS Match | U9: =IF(ISNUMBER(MATCH($D9,Disability!$B$2:$B$5962,0)),"SPED","Gen Ed") -> Gen Ed
A10: Southside 291462 | B10: 46174 | C10: southside_291462_unified-roster.xlsx | D10: 9622581930 | E10: 210014483 | F10: Dennis | G10: Arhianna | H10: 1 | I10: 43699 | J10: Southside Academy Charter School | K10: 45904 | L10: 45994 | M10: 0.3 | N10: No Good | O10: ST states: student enrolled at Southside Academy Charter School 8/16/25.25 11/25/25. Enrolled at HW Smith PK-8 12/1/25 - current. Entry date 3> day discrepancy. Need charter attendance record to change in ST. | P10: Gen Ed | Q10: =IFERROR(INDEX('ST Enroll Export'!$A$2:$A$3230,MATCH($D10,'ST Enroll Export'!$A$2:$A$3230,0)),IFERROR(IF(INDEX('ST Enroll Export'!$A$2:$A$3230,MATCH($E10,'ST Enroll Export'!$B$2:$B$3230,0))="","",INDEX('ST Enroll Export'!$A$2:$A$3230,MATCH($E10,'ST Enroll Export'!$B$2:$B$3230,0))),"Not Found")) -> 9622581930 | R10: =IFERROR(INDEX('ST Enroll Export'!$G$2:$G$3230,MATCH($D10,'ST Enroll Export'!$A$2:$A$3230,0)),IFERROR(INDEX('ST Enroll Export'!$G$2:$G$3230,MATCH($E10,'ST Enroll Export'!$B$2:$B$3230,0)),"Not Found")) -> Southside Academy Charter School | S10: =IFERROR(INDEX('ST Enroll Export'!$B$2:$B$3230,MATCH($D10,'ST Enroll Export'!$A$2:$A$3230,0)),IFERROR(INDEX('ST Enroll Export'!$B$2:$B$3230,MATCH($E10,'ST Enroll Export'!$B$2:$B$3230,0)),"Not Found")) -> 210014483 | T10: =IF(ISNUMBER(MATCH($D10,'ST Enroll Export'!$A$2:$A$3230,0)),"NYSSIS Match",IF(ISNUMBER(MATCH($E10,'ST Enroll Export'!$B$2:$B$3230,0)),"SID Match","No ST Match")) -> NYSSIS Match | U10: =IF(ISNUMBER(MATCH($D10,Disability!$B$2:$B$5962,0)),"SPED","Gen Ed") -> Gen Ed
A11: Southside 291462 | B11: 46174 | C11: southside_291462_unified-roster.xlsx | D11: 8381796603 | F11: Loper | G11: Bobby | H11: K | I11: 44194 | J11: Southside Academy Charter School | K11: 45903 | M11: 1 | N11: No Good | O11: ST states:No 25-26 charter shool enrollment entry in ST student enrolled at Bellevue ES 7/1/25-9/10/25. | P11: Gen Ed | Q11: =IFERROR(INDEX('ST Enroll Export'!$A$2:$A$3230,MATCH($D11,'ST Enroll Export'!$A$2:$A$3230,0)),IFERROR(IF(INDEX('ST Enroll Export'!$A$2:$A$3230,MATCH($E11,'ST Enroll Export'!$B$2:$B$3230,0))="","",INDEX('ST Enroll Export'!$A$2:$A$3230,MATCH($E11,'ST Enroll Export'!$B$2:$B$3230,0))),"Not Found")) -> Not Found | R11: =IFERROR(INDEX('ST Enroll Export'!$G$2:$G$3230,MATCH($D11,'ST Enroll Export'!$A$2:$A$3230,0)),IFERROR(INDEX('ST Enroll Export'!$G$2:$G$3230,MATCH($E11,'ST Enroll Export'!$B$2:$B$3230,0)),"Not Found")) -> Not Found | S11: =IFERROR(INDEX('ST Enroll Export'!$B$2:$B$3230,MATCH($D11,'ST Enroll Export'!$A$2:$A$3230,0)),IFERROR(INDEX('ST Enroll Export'!$B$2:$B$3230,MATCH($E11,'ST Enroll Export'!$B$2:$B$3230,0)),"Not Found")) -> Not Found | T11: =IF(ISNUMBER(MATCH($D11,'ST Enroll Export'!$A$2:$A$3230,0)),"NYSSIS Match",IF(ISNUMBER(MATCH($E11,'ST Enroll Export'!$B$2:$B$3230,0)),"SID Match","No ST Match")) -> No ST Match | U11: =IF(ISNUMBER(MATCH($D11,Disability!$B$2:$B$5962,0)),"SPED","Gen Ed") -> Gen Ed
A12: Southside 291462 | B12: 46174 | C12: southside_291462_unified-roster.xlsx | D12: 8993227873 | E12: 210019759 | F12: Reome | G12: Caylyn | H12: 1 | I12: 43543 | J12: Southside Academy Charter School | K12: 45903 | L12: 45915 | M12: 0.05 | N12: No Good | O12: ST states: student enrolled at Southside Academy 7/1/25 - 9/11/25. Exit date 3> day discrepancy. Need charter attendance record to change in ST. Enrolled at Syracuse Academy of Science Elementary at St James 9/12/25 | P12: Gen Ed | Q12: =IFERROR(INDEX('ST Enroll Export'!$A$2:$A$3230,MATCH($D12,'ST Enroll Export'!$A$2:$A$3230,0)),IFERROR(IF(INDEX('ST Enroll Export'!$A$2:$A$3230,MATCH($E12,'ST Enroll Export'!$B$2:$B$3230,0))="","",INDEX('ST Enroll Export'!$A$2:$A$3230,MATCH($E12,'ST Enroll Export'!$B$2:$B$3230,0))),"Not Found")) -> 8993227873 | R12: =IFERROR(INDEX('ST Enroll Export'!$G$2:$G$3230,MATCH($D12,'ST Enroll Export'!$A$2:$A$3230,0)),IFERROR(INDEX('ST Enroll Export'!$G$2:$G$3230,MATCH($E12,'ST Enroll Export'!$B$2:$B$3230,0)),"Not Found")) -> Southside Academy Charter School | S12: =IFERROR(INDEX('ST Enroll Export'!$B$2:$B$3230,MATCH($D12,'ST Enroll Export'!$A$2:$A$3230,0)),IFERROR(INDEX('ST Enroll Export'!$B$2:$B$3230,MATCH($E12,'ST Enroll Export'!$B$2:$B$3230,0)),"Not Found")) -> 210019759 | T12: =IF(ISNUMBER(MATCH($D12,'ST Enroll Export'!$A$2:$A$3230,0)),"NYSSIS Match",IF(ISNUMBER(MATCH($E12,'ST Enroll Export'!$B$2:$B$3230,0)),"SID Match","No ST Match")) -> NYSSIS Match | U12: =IF(ISNUMBER(MATCH($D12,Disability!$B$2:$B$5962,0)),"SPED","Gen Ed") -> Gen Ed
A13: Southside 291462 | B13: 46174 | C13: southside_291462_unified-roster.xlsx | D13: 5531469482 | E13: 210003314 | F13: Reome Jr. | G13: Christopher | H13: 3 | I13: 42876 | J13: Southside Academy Charter School | K13: 45903 | L13: 45915 | M13: 0.05 | N13: No Good | O13: ST states: student enrolled at Southside Academy 7/1/25 - 9/11/25. Exit date 3> day discrepancy. Need charter attendance record to change in ST. Enrolled at Syracuse Academy of Science Elementary at St James 9/12/25 | P13: Gen Ed | Q13: =IFERROR(INDEX('ST Enroll Export'!$A$2:$A$3230,MATCH($D13,'ST Enroll Export'!$A$2:$A$3230,0)),IFERROR(IF(INDEX('ST Enroll Export'!$A$2:$A$3230,MATCH($E13,'ST Enroll Export'!$B$2:$B$3230,0))="","",INDEX('ST Enroll Export'!$A$2:$A$3230,MATCH($E13,'ST Enroll Export'!$B$2:$B$3230,0))),"Not Found")) -> 5531469482 | R13: =IFERROR(INDEX('ST Enroll Export'!$G$2:$G$3230,MATCH($D13,'ST Enroll Export'!$A$2:$A$3230,0)),IFERROR(INDEX('ST Enroll Export'!$G$2:$G$3230,MATCH($E13,'ST Enroll Export'!$B$2:$B$3230,0)),"Not Found")) -> Southside Academy Charter School | S13: =IFERROR(INDEX('ST Enroll Export'!$B$2:$B$3230,MATCH($D13,'ST Enroll Export'!$A$2:$A$3230,0)),IFERROR(INDEX('ST Enroll Export'!$B$2:$B$3230,MATCH($E13,'ST Enroll Export'!$B$2:$B$3230,0)),"Not Found")) -> 210003314 | T13: =IF(ISNUMBER(MATCH($D13,'ST Enroll Export'!$A$2:$A$3230,0)),"NYSSIS Match",IF(ISNUMBER(MATCH($E13,'ST Enroll Export'!$B$2:$B$3230,0)),"SID Match","No ST Match")) -> NYSSIS Match | U13: =IF(ISNUMBER(MATCH($D13,Disability!$B$2:$B$5962,0)),"SPED","Gen Ed") -> Gen Ed
A14: Southside 291462 | B14: 46174 | C14: southside_291462_unified-roster.xlsx | D14: 7205350121 | E14: 210018482 | F14: Davis | G14: Cyh'Mora | H14: 1 | I14: 43826 | J14: Southside Academy Charter School | K14: 45903 | M14: 1 | N14: No Good | O14: ST states: student enrolled at Southside Academy Charter School9/25/25 - current. Entry date 3> day discrepancy. Need charter attendance record to change in ST. | P14: Gen Ed | Q14: =IFERROR(INDEX('ST Enroll Export'!$A$2:$A$3230,MATCH($D14,'ST Enroll Export'!$A$2:$A$3230,0)),IFERROR(IF(INDEX('ST Enroll Export'!$A$2:$A$3230,MATCH($E14,'ST Enroll Export'!$B$2:$B$3230,0))="","",INDEX('ST Enroll Export'!$A$2:$A$3230,MATCH($E14,'ST Enroll Export'!$B$2:$B$3230,0))),"Not Found")) -> 7205350121 | R14: =IFERROR(INDEX('ST Enroll Export'!$G$2:$G$3230,MATCH($D14,'ST Enroll Export'!$A$2:$A$3230,0)),IFERROR(INDEX('ST Enroll Export'!$G$2:$G$3230,MATCH($E14,'ST Enroll Export'!$B$2:$B$3230,0)),"Not Found")) -> Southside Academy Charter School | S14: =IFERROR(INDEX('ST Enroll Export'!$B$2:$B$3230,MATCH($D14,'ST Enroll Export'!$A$2:$A$3230,0)),IFERROR(INDEX('ST Enroll Export'!$B$2:$B$3230,MATCH($E14,'ST Enroll Export'!$B$2:$B$3230,0)),"Not Found")) -> 210018482 | T14: =IF(ISNUMBER(MATCH($D14,'ST Enroll Export'!$A$2:$A$3230,0)),"NYSSIS Match",IF(ISNUMBER(MATCH($E14,'ST Enroll Export'!$B$2:$B$3230,0)),"SID Match","No ST Match")) -> NYSSIS Match | U14: =IF(ISNUMBER(MATCH($D14,Disability!$B$2:$B$5962,0)),"SPED","Gen Ed") -> Gen Ed
A15: Southside 291462 | B15: 46174 | C15: southside_291462_unified-roster.xlsx | D15: 4427385530 | F15: 0 | G15: Donald | H15: K | I15: 44172 | J15: Southside Academy Charter School | K15: 45903 | M15: 1 | N15: Not in ST System | O15: Not pulling up in ST. Need more student information. NYSSIS ID, Last name,grade,parent info, gender, race, etc. | P15: Gen Ed | Q15: =IFERROR(INDEX('ST Enroll Export'!$A$2:$A$3230,MATCH($D15,'ST Enroll Export'!$A$2:$A$3230,0)),IFERROR(IF(INDEX('ST Enroll Export'!$A$2:$A$3230,MATCH($E15,'ST Enroll Export'!$B$2:$B$3230,0))="","",INDEX('ST Enroll Export'!$A$2:$A$3230,MATCH($E15,'ST Enroll Export'!$B$2:$B$3230,0))),"Not Found")) -> Not Found | R15: =IFERROR(INDEX('ST Enroll Export'!$G$2:$G$3230,MATCH($D15,'ST Enroll Export'!$A$2:$A$3230,0)),IFERROR(INDEX('ST Enroll Export'!$G$2:$G$3230,MATCH($E15,'ST Enroll Export'!$B$2:$B$3230,0)),"Not Found")) -> Not Found | S15: =IFERROR(INDEX('ST Enroll Export'!$B$2:$B$3230,MATCH($D15,'ST Enroll Export'!$A$2:$A$3230,0)),IFERROR(INDEX('ST Enroll Export'!$B$2:$B$3230,MATCH($E15,'ST Enroll Export'!$B$2:$B$3230,0)),"Not Found")) -> Not Found | T15: =IF(ISNUMBER(MATCH($D15,'ST Enroll Export'!$A$2:$A$3230,0)),"NYSSIS Match",IF(ISNUMBER(MATCH($E15,'ST Enroll Export'!$B$2:$B$3230,0)),"SID Match","No ST Match")) -> No ST Match | U15: =IF(ISNUMBER(MATCH($D15,Disability!$B$2:$B$5962,0)),"SPED","Gen Ed") -> Gen Ed
A16: Southside 291462 | B16: 46174 | C16: southside_291462_unified-roster.xlsx | D16: 5481567902 | E16: 210022691 | F16: Hatfield | G16: Draylan | H16: K | I16: 43853 | J16: Southside Academy Charter School | K16: 45905 | M16: 0.975 | N16: No Good | O16: ST states: student enrolled at Southside Academy Charter School 10/28/25 - current. Entry date 3> day discrepancy. Need charter attendance record to change in ST. | P16: SPED | Q16: =IFERROR(INDEX('ST Enroll Export'!$A$2:$A$3230,MATCH($D16,'ST Enroll Export'!$A$2:$A$3230,0)),IFERROR(IF(INDEX('ST Enroll Export'!$A$2:$A$3230,MATCH($E16,'ST Enroll Export'!$B$2:$B$3230,0))="","",INDEX('ST Enroll Export'!$A$2:$A$3230,MATCH($E16,'ST Enroll Export'!$B$2:$B$3230,0))),"Not Found")) -> 5481567902 | R16: =IFERROR(INDEX('ST Enroll Export'!$G$2:$G$3230,MATCH($D16,'ST Enroll Export'!$A$2:$A$3230,0)),IFERROR(INDEX('ST Enroll Export'!$G$2:$G$3230,MATCH($E16,'ST Enroll Export'!$B$2:$B$3230,0)),"Not Found")) -> Southside Academy Charter School | S16: =IFERROR(INDEX('ST Enroll Export'!$B$2:$B$3230,MATCH($D16,'ST Enroll Export'!$A$2:$A$3230,0)),IFERROR(INDEX('ST Enroll Export'!$B$2:$B$3230,MATCH($E16,'ST Enroll Export'!$B$2:$B$3230,0)),"Not Found")) -> 210022691 | T16: =IF(ISNUMBER(MATCH($D16,'ST Enroll Export'!$A$2:$A$3230,0)),"NYSSIS Match",IF(ISNUMBER(MATCH($E16,'ST Enroll Export'!$B$2:$B$3230,0)),"SID Match","No ST Match")) -> NYSSIS Match | U16: =IF(ISNUMBER(MATCH($D16,Disability!$B$2:$B$5962,0)),"SPED","Gen Ed") -> SPED
A17: Southside 291462 | B17: 46174 | C17: southside_291462_unified-roster.xlsx | D17: 9345645621 | F17: 0 | G17: Edward | H17: K | I17: 43910 | J17: Southside Academy Charter School | K17: 45918 | M17: 0.925 | N17: Not in ST System | O17: Not pulling up in ST. Need more student information. NYSSIS ID, Last name,grade,parent info, gender, race, etc. | P17: Gen Ed | Q17: =IFERROR(INDEX('ST Enroll Export'!$A$2:$A$3230,MATCH($D17,'ST Enroll Export'!$A$2:$A$3230,0)),IFERROR(IF(INDEX('ST Enroll Export'!$A$2:$A$3230,MATCH($E17,'ST Enroll Export'!$B$2:$B$3230,0))="","",INDEX('ST Enroll Export'!$A$2:$A$3230,MATCH($E17,'ST Enroll Export'!$B$2:$B$3230,0))),"Not Found")) -> Not Found | R17: =IFERROR(INDEX('ST Enroll Export'!$G$2:$G$3230,MATCH($D17,'ST Enroll Export'!$A$2:$A$3230,0)),IFERROR(INDEX('ST Enroll Export'!$G$2:$G$3230,MATCH($E17,'ST Enroll Export'!$B$2:$B$3230,0)),"Not Found")) -> Not Found | S17: =IFERROR(INDEX('ST Enroll Export'!$B$2:$B$3230,MATCH($D17,'ST Enroll Export'!$A$2:$A$3230,0)),IFERROR(INDEX('ST Enroll Export'!$B$2:$B$3230,MATCH($E17,'ST Enroll Export'!$B$2:$B$3230,0)),"Not Found")) -> Not Found | T17: =IF(ISNUMBER(MATCH($D17,'ST Enroll Export'!$A$2:$A$3230,0)),"NYSSIS Match",IF(ISNUMBER(MATCH($E17,'ST Enroll Export'!$B$2:$B$3230,0)),"SID Match","No ST Match")) -> No ST Match | U17: =IF(ISNUMBER(MATCH($D17,Disability!$B$2:$B$5962,0)),"SPED","Gen Ed") -> Gen Ed
A18: Southside 291462 | B18: 46174 | C18: southside_291462_unified-roster.xlsx | D18: 3226816591 | E18: 210018247 | F18: Giddings | G18: Gracie | H18: K | I18: 44192 | J18: Southside Academy Charter School | K18: 45904 | M18: 0.975 | N18: No Good | O18: ST states: student enrolled at Southside Academy Charter School 1/7/25- current. Entry date 3> day discrepancy. Need charter attendance record to change in ST. | P18: Gen Ed | Q18: =IFERROR(INDEX('ST Enroll Export'!$A$2:$A$3230,MATCH($D18,'ST Enroll Export'!$A$2:$A$3230,0)),IFERROR(IF(INDEX('ST Enroll Export'!$A$2:$A$3230,MATCH($E18,'ST Enroll Export'!$B$2:$B$3230,0))="","",INDEX('ST Enroll Export'!$A$2:$A$3230,MATCH($E18,'ST Enroll Export'!$B$2:$B$3230,0))),"Not Found")) -> 3226816591 | R18: =IFERROR(INDEX('ST Enroll Export'!$G$2:$G$3230,MATCH($D18,'ST Enroll Export'!$A$2:$A$3230,0)),IFERROR(INDEX('ST Enroll Export'!$G$2:$G$3230,MATCH($E18,'ST Enroll Export'!$B$2:$B$3230,0)),"Not Found")) -> Southside Academy Charter School | S18: =IFERROR(INDEX('ST Enroll Export'!$B$2:$B$3230,MATCH($D18,'ST Enroll Export'!$A$2:$A$3230,0)),IFERROR(INDEX('ST Enroll Export'!$B$2:$B$3230,MATCH($E18,'ST Enroll Export'!$B$2:$B$3230,0)),"Not Found")) -> 210018247 | T18: =IF(ISNUMBER(MATCH($D18,'ST Enroll Export'!$A$2:$A$3230,0)),"NYSSIS Match",IF(ISNUMBER(MATCH($E18,'ST Enroll Export'!$B$2:$B$3230,0)),"SID Match","No ST Match")) -> NYSSIS Match | U18: =IF(ISNUMBER(MATCH($D18,Disability!$B$2:$B$5962,0)),"SPED","Gen Ed") -> Gen Ed
A19: Southside 291462 | B19: 46174 | C19: southside_291462_unified-roster.xlsx | D19: 8891043605 | E19: 210011263 | F19: Maldonado | G19: INessa | H19: 2 | I19: 43358 | J19: Southside Academy Charter School | K19: 45910 | M19: 0.975 | N19: No Good | O19: ST states: student enrolled at Southside Academy Charter School 11/5/25- current. Entry date 3> day discrepancy. Need charter attendance record to change in ST. | P19: SPED | Q19: =IFERROR(INDEX('ST Enroll Export'!$A$2:$A$3230,MATCH($D19,'ST Enroll Export'!$A$2:$A$3230,0)),IFERROR(IF(INDEX('ST Enroll Export'!$A$2:$A$3230,MATCH($E19,'ST Enroll Export'!$B$2:$B$3230,0))="","",INDEX('ST Enroll Export'!$A$2:$A$3230,MATCH($E19,'ST Enroll Export'!$B$2:$B$3230,0))),"Not Found")) -> 8891043605 | R19: =IFERROR(INDEX('ST Enroll Export'!$G$2:$G$3230,MATCH($D19,'ST Enroll Export'!$A$2:$A$3230,0)),IFERROR(INDEX('ST Enroll Export'!$G$2:$G$3230,MATCH($E19,'ST Enroll Export'!$B$2:$B$3230,0)),"Not Found")) -> Southside Academy Charter School | S19: =IFERROR(INDEX('ST Enroll Export'!$B$2:$B$3230,MATCH($D19,'ST Enroll Export'!$A$2:$A$3230,0)),IFERROR(INDEX('ST Enroll Export'!$B$2:$B$3230,MATCH($E19,'ST Enroll Export'!$B$2:$B$3230,0)),"Not Found")) -> 210011263 | T19: =IF(ISNUMBER(MATCH($D19,'ST Enroll Export'!$A$2:$A$3230,0)),"NYSSIS Match",IF(ISNUMBER(MATCH($E19,'ST Enroll Export'!$B$2:$B$3230,0)),"SID Match","No ST Match")) -> NYSSIS Match | U19: =IF(ISNUMBER(MATCH($D19,Disability!$B$2:$B$5962,0)),"SPED","Gen Ed") -> SPED
A20: Southside 291462 | B20: 46174 | C20: southside_291462_unified-roster.xlsx | D20: 6207168494 | E20: 200038985 | F20: Sallard | G20: Jaliyah | H20: 4 | I20: 42561 | J20: Southside Academy Charter School | K20: 45915 | M20: 0.95 | N20: No Good | O20: ST states: student enrolled at Southside Academy Charter School 9/24/25- current. Entry date 3> day discrepancy. Need charter attendance record to change in ST. | P20: Gen Ed | Q20: =IFERROR(INDEX('ST Enroll Export'!$A$2:$A$3230,MATCH($D20,'ST Enroll Export'!$A$2:$A$3230,0)),IFERROR(IF(INDEX('ST Enroll Export'!$A$2:$A$3230,MATCH($E20,'ST Enroll Export'!$B$2:$B$3230,0))="","",INDEX('ST Enroll Export'!$A$2:$A$3230,MATCH($E20,'ST Enroll Export'!$B$2:$B$3230,0))),"Not Found")) -> 6207168494 | R20: =IFERROR(INDEX('ST Enroll Export'!$G$2:$G$3230,MATCH($D20,'ST Enroll Export'!$A$2:$A$3230,0)),IFERROR(INDEX('ST Enroll Export'!$G$2:$G$3230,MATCH($E20,'ST Enroll Export'!$B$2:$B$3230,0)),"Not Found")) -> Southside Academy Charter School | S20: =IFERROR(INDEX('ST Enroll Export'!$B$2:$B$3230,MATCH($D20,'ST Enroll Export'!$A$2:$A$3230,0)),IFERROR(INDEX('ST Enroll Export'!$B$2:$B$3230,MATCH($E20,'ST Enroll Export'!$B$2:$B$3230,0)),"Not Found")) -> 200038985 | T20: =IF(ISNUMBER(MATCH($D20,'ST Enroll Export'!$A$2:$A$3230,0)),"NYSSIS Match",IF(ISNUMBER(MATCH($E20,'ST Enroll Export'!$B$2:$B$3230,0)),"SID Match","No ST Match")) -> NYSSIS Match | U20: =IF(ISNUMBER(MATCH($D20,Disability!$B$2:$B$5962,0)),"SPED","Gen Ed") -> Gen Ed
A21: Southside 291462 | B21: 46174 | C21: southside_291462_unified-roster.xlsx | D21: 7360992380 | E21: 210022689 | F21: Vaughns | G21: Jayceon | H21: 2 | I21: 43318 | J21: Southside Academy Charter School | K21: 45905 | M21: 0.975 | N21: No Good | O21: ST states: student enrolled at Southside Academy Charter School 10/28/25- current. Entry date 3> day discrepancy. Need charter attendance record to change in ST. | P21: SPED | Q21: =IFERROR(INDEX('ST Enroll Export'!$A$2:$A$3230,MATCH($D21,'ST Enroll Export'!$A$2:$A$3230,0)),IFERROR(IF(INDEX('ST Enroll Export'!$A$2:$A$3230,MATCH($E21,'ST Enroll Export'!$B$2:$B$3230,0))="","",INDEX('ST Enroll Export'!$A$2:$A$3230,MATCH($E21,'ST Enroll Export'!$B$2:$B$3230,0))),"Not Found")) -> 7360992380 | R21: =IFERROR(INDEX('ST Enroll Export'!$G$2:$G$3230,MATCH($D21,'ST Enroll Export'!$A$2:$A$3230,0)),IFERROR(INDEX('ST Enroll Export'!$G$2:$G$3230,MATCH($E21,'ST Enroll Export'!$B$2:$B$3230,0)),"Not Found")) -> Southside Academy Charter School | S21: =IFERROR(INDEX('ST Enroll Export'!$B$2:$B$3230,MATCH($D21,'ST Enroll Export'!$A$2:$A$3230,0)),IFERROR(INDEX('ST Enroll Export'!$B$2:$B$3230,MATCH($E21,'ST Enroll Export'!$B$2:$B$3230,0)),"Not Found")) -> 210022689 | T21: =IF(ISNUMBER(MATCH($D21,'ST Enroll Export'!$A$2:$A$3230,0)),"NYSSIS Match",IF(ISNUMBER(MATCH($E21,'ST Enroll Export'!$B$2:$B$3230,0)),"SID Match","No ST Match")) -> NYSSIS Match | U21: =IF(ISNUMBER(MATCH($D21,Disability!$B$2:$B$5962,0)),"SPED","Gen Ed") -> SPED
A22: Southside 291462 | B22: 46174 | C22: southside_291462_unified-roster.xlsx | D22: 9316354706 | E22: 210014757 | F22: Jackson | G22: Jordyn | H22: K | I22: 44128 | J22: Southside Academy Charter School | K22: 45903 | M22: 1 | N22: No Good | O22: ST states: student enrolled at Syracuse Academy of Science Elementary at St James 8/15/25 - 9/14/25. Enrolled at Southside Academy 9/15/25 - current. Entry 3> day discrepancy. Need charter attendance record to change in ST. | P22: Gen Ed | Q22: =IFERROR(INDEX('ST Enroll Export'!$A$2:$A$3230,MATCH($D22,'ST Enroll Export'!$A$2:$A$3230,0)),IFERROR(IF(INDEX('ST Enroll Export'!$A$2:$A$3230,MATCH($E22,'ST Enroll Export'!$B$2:$B$3230,0))="","",INDEX('ST Enroll Export'!$A$2:$A$3230,MATCH($E22,'ST Enroll Export'!$B$2:$B$3230,0))),"Not Found")) -> 9316354706 | R22: =IFERROR(INDEX('ST Enroll Export'!$G$2:$G$3230,MATCH($D22,'ST Enroll Export'!$A$2:$A$3230,0)),IFERROR(INDEX('ST Enroll Export'!$G$2:$G$3230,MATCH($E22,'ST Enroll Export'!$B$2:$B$3230,0)),"Not Found")) -> Southside Academy Charter School | S22: =IFERROR(INDEX('ST Enroll Export'!$B$2:$B$3230,MATCH($D22,'ST Enroll Export'!$A$2:$A$3230,0)),IFERROR(INDEX('ST Enroll Export'!$B$2:$B$3230,MATCH($E22,'ST Enroll Export'!$B$2:$B$3230,0)),"Not Found")) -> 210014757 | T22: =IF(ISNUMBER(MATCH($D22,'ST Enroll Export'!$A$2:$A$3230,0)),"NYSSIS Match",IF(ISNUMBER(MATCH($E22,'ST Enroll Export'!$B$2:$B$3230,0)),"SID Match","No ST Match")) -> NYSSIS Match | U22: =IF(ISNUMBER(MATCH($D22,Disability!$B$2:$B$5962,0)),"SPED","Gen Ed") -> Gen Ed
A23: Southside 291462 | B23: 46174 | C23: southside_291462_unified-roster.xlsx | F23: 0 | G23: Josiah | H23: 7 | I23: 41450 | J23: Southside Academy Charter School | K23: 45903 | M23: 1 | N23: Not in ST System | O23: Not pulling up in ST. | P23: Gen Ed | Q23: =IFERROR(INDEX('ST Enroll Export'!$A$2:$A$3230,MATCH($D23,'ST Enroll Export'!$A$2:$A$3230,0)),IFERROR(IF(INDEX('ST Enroll Export'!$A$2:$A$3230,MATCH($E23,'ST Enroll Export'!$B$2:$B$3230,0))="","",INDEX('ST Enroll Export'!$A$2:$A$3230,MATCH($E23,'ST Enroll Export'!$B$2:$B$3230,0))),"Not Found")) -> Not Found | R23: =IFERROR(INDEX('ST Enroll Export'!$G$2:$G$3230,MATCH($D23,'ST Enroll Export'!$A$2:$A$3230,0)),IFERROR(INDEX('ST Enroll Export'!$G$2:$G$3230,MATCH($E23,'ST Enroll Export'!$B$2:$B$3230,0)),"Not Found")) -> Not Found | S23: =IFERROR(INDEX('ST Enroll Export'!$B$2:$B$3230,MATCH($D23,'ST Enroll Export'!$A$2:$A$3230,0)),IFERROR(INDEX('ST Enroll Export'!$B$2:$B$3230,MATCH($E23,'ST Enroll Export'!$B$2:$B$3230,0)),"Not Found")) -> Not Found | T23: =IF(ISNUMBER(MATCH($D23,'ST Enroll Export'!$A$2:$A$3230,0)),"NYSSIS Match",IF(ISNUMBER(MATCH($E23,'ST Enroll Export'!$B$2:$B$3230,0)),"SID Match","No ST Match")) -> No ST Match | U23: =IF(ISNUMBER(MATCH($D23,Disability!$B$2:$B$5962,0)),"SPED","Gen Ed") -> Gen Ed
A24: Southside 291462 | B24: 46174 | C24: southside_291462_unified-roster.xlsx | D24: 4148681903 | E24: 210019004 | F24: Robertson | G24: Jovanni | H24: 1 | I24: 43725 | J24: Citizenship & Science Academy of Syracuse Charter | K24: 45903 | M24: 1 | N24: No Good | O24: ST states: student enrolled at Citizenship & Science Academy of Syracuse Charter 7/1/25 - 9/10/25.. Enrolled at Southside Academy 9/24/25 - current. Entry 3> day discrepancy. Need charter attendance record to change in ST. | P24: Gen Ed | Q24: =IFERROR(INDEX('ST Enroll Export'!$A$2:$A$3230,MATCH($D24,'ST Enroll Export'!$A$2:$A$3230,0)),IFERROR(IF(INDEX('ST Enroll Export'!$A$2:$A$3230,MATCH($E24,'ST Enroll Export'!$B$2:$B$3230,0))="","",INDEX('ST Enroll Export'!$A$2:$A$3230,MATCH($E24,'ST Enroll Export'!$B$2:$B$3230,0))),"Not Found")) -> 4148681903 | R24: =IFERROR(INDEX('ST Enroll Export'!$G$2:$G$3230,MATCH($D24,'ST Enroll Export'!$A$2:$A$3230,0)),IFERROR(INDEX('ST Enroll Export'!$G$2:$G$3230,MATCH($E24,'ST Enroll Export'!$B$2:$B$3230,0)),"Not Found")) -> Citizenship & Science Academy of Syracuse Charter | S24: =IFERROR(INDEX('ST Enroll Export'!$B$2:$B$3230,MATCH($D24,'ST Enroll Export'!$A$2:$A$3230,0)),IFERROR(INDEX('ST Enroll Export'!$B$2:$B$3230,MATCH($E24,'ST Enroll Export'!$B$2:$B$3230,0)),"Not Found")) -> 210019004 | T24: =IF(ISNUMBER(MATCH($D24,'ST Enroll Export'!$A$2:$A$3230,0)),"NYSSIS Match",IF(ISNUMBER(MATCH($E24,'ST Enroll Export'!$B$2:$B$3230,0)),"SID Match","No ST Match")) -> NYSSIS Match | U24: =IF(ISNUMBER(MATCH($D24,Disability!$B$2:$B$5962,0)),"SPED","Gen Ed") -> Gen Ed
A25: Southside 291462 | B25: 46174 | C25: southside_291462_unified-roster.xlsx | D25: 3321809294 | E25: 200033900 | F25: Anderson | G25: Juelez | H25: 5 | I25: 41625 | J25: Southside Academy Charter School | K25: 45903 | L25: 45995 | M25: 0.325 | N25: No Good | O25: ST states: student enrolled at Southside Academy Charter School 7/1/25- 11/24/25. Enrolled at STEAM @ Dr King / ES 11/25/25- current. Entry date 3> day discrepancy. Need charter attendance record to change in ST. | P25: SPED | Q25: =IFERROR(INDEX('ST Enroll Export'!$A$2:$A$3230,MATCH($D25,'ST Enroll Export'!$A$2:$A$3230,0)),IFERROR(IF(INDEX('ST Enroll Export'!$A$2:$A$3230,MATCH($E25,'ST Enroll Export'!$B$2:$B$3230,0))="","",INDEX('ST Enroll Export'!$A$2:$A$3230,MATCH($E25,'ST Enroll Export'!$B$2:$B$3230,0))),"Not Found")) -> 3321809294 | R25: =IFERROR(INDEX('ST Enroll Export'!$G$2:$G$3230,MATCH($D25,'ST Enroll Export'!$A$2:$A$3230,0)),IFERROR(INDEX('ST Enroll Export'!$G$2:$G$3230,MATCH($E25,'ST Enroll Export'!$B$2:$B$3230,0)),"Not Found")) -> Southside Academy Charter School | S25: =IFERROR(INDEX('ST Enroll Export'!$B$2:$B$3230,MATCH($D25,'ST Enroll Export'!$A$2:$A$3230,0)),IFERROR(INDEX('ST Enroll Export'!$B$2:$B$3230,MATCH($E25,'ST Enroll Export'!$B$2:$B$3230,0)),"Not Found")) -> 200033900 | T25: =IF(ISNUMBER(MATCH($D25,'ST Enroll Export'!$A$2:$A$3230,0)),"NYSSIS Match",IF(ISNUMBER(MATCH($E25,'ST Enroll Export'!$B$2:$B$3230,0)),"SID Match","No ST Match")) -> NYSSIS Match | U25: =IF(ISNUMBER(MATCH($D25,Disability!$B$2:$B$5962,0)),"SPED","Gen Ed") -> SPED
A26: Southside 291462 | B26: 46174 | C26: southside_291462_unified-roster.xlsx | D26: 2807672461 | E26: 200024256 | F26: Cenzalli JR | G26: Justin | H26: 8 | I26: 41042 | J26: Southside Academy Charter School | K26: 45903 | L26: 45919 | M26: 0.075 | N26: No Good | O26: ST states: student enrolled at Southside Academy Charter School 9/6/25 - 9/11/25. Enrolled at Ed Smith PK-8 / MS 9/18/25- 2/6/25. Entry date 3> day discrepancy. Need charter attendance record to change in ST. | P26: SPED | Q26: =IFERROR(INDEX('ST Enroll Export'!$A$2:$A$3230,MATCH($D26,'ST Enroll Export'!$A$2:$A$3230,0)),IFERROR(IF(INDEX('ST Enroll Export'!$A$2:$A$3230,MATCH($E26,'ST Enroll Export'!$B$2:$B$3230,0))="","",INDEX('ST Enroll Export'!$A$2:$A$3230,MATCH($E26,'ST Enroll Export'!$B$2:$B$3230,0))),"Not Found")) -> 2807672461 | R26: =IFERROR(INDEX('ST Enroll Export'!$G$2:$G$3230,MATCH($D26,'ST Enroll Export'!$A$2:$A$3230,0)),IFERROR(INDEX('ST Enroll Export'!$G$2:$G$3230,MATCH($E26,'ST Enroll Export'!$B$2:$B$3230,0)),"Not Found")) -> Southside Academy Charter School | S26: =IFERROR(INDEX('ST Enroll Export'!$B$2:$B$3230,MATCH($D26,'ST Enroll Export'!$A$2:$A$3230,0)),IFERROR(INDEX('ST Enroll Export'!$B$2:$B$3230,MATCH($E26,'ST Enroll Export'!$B$2:$B$3230,0)),"Not Found")) -> 200024256 | T26: =IF(ISNUMBER(MATCH($D26,'ST Enroll Export'!$A$2:$A$3230,0)),"NYSSIS Match",IF(ISNUMBER(MATCH($E26,'ST Enroll Export'!$B$2:$B$3230,0)),"SID Match","No ST Match")) -> NYSSIS Match | U26: =IF(ISNUMBER(MATCH($D26,Disability!$B$2:$B$5962,0)),"SPED","Gen Ed") -> SPED
A27: Southside 291462 | B27: 46174 | C27: southside_291462_unified-roster.xlsx | D27: 3908940154 | E27: 210002244 | F27: Lobban | G27: Kahwi | H27: 5 | I27: 41841 | J27: Southside Academy Charter School | K27: 45904 | L27: 45923 | M27: 0.05 | N27: No Good | O27: ST states: student enrolled at Southside Academy Charter School 7/1/25 - 9/8/25. Enrolled at STEAM @ Dr King / ES 9/18/25 - current. Entry date 3> day discrepancy. Need charter attendance record to change in ST. | P27: SPED | Q27: =IFERROR(INDEX('ST Enroll Export'!$A$2:$A$3230,MATCH($D27,'ST Enroll Export'!$A$2:$A$3230,0)),IFERROR(IF(INDEX('ST Enroll Export'!$A$2:$A$3230,MATCH($E27,'ST Enroll Export'!$B$2:$B$3230,0))="","",INDEX('ST Enroll Export'!$A$2:$A$3230,MATCH($E27,'ST Enroll Export'!$B$2:$B$3230,0))),"Not Found")) -> 3908940154 | R27: =IFERROR(INDEX('ST Enroll Export'!$G$2:$G$3230,MATCH($D27,'ST Enroll Export'!$A$2:$A$3230,0)),IFERROR(INDEX('ST Enroll Export'!$G$2:$G$3230,MATCH($E27,'ST Enroll Export'!$B$2:$B$3230,0)),"Not Found")) -> Southside Academy Charter School | S27: =IFERROR(INDEX('ST Enroll Export'!$B$2:$B$3230,MATCH($D27,'ST Enroll Export'!$A$2:$A$3230,0)),IFERROR(INDEX('ST Enroll Export'!$B$2:$B$3230,MATCH($E27,'ST Enroll Export'!$B$2:$B$3230,0)),"Not Found")) -> 210002244 | T27: =IF(ISNUMBER(MATCH($D27,'ST Enroll Export'!$A$2:$A$3230,0)),"NYSSIS Match",IF(ISNUMBER(MATCH($E27,'ST Enroll Export'!$B$2:$B$3230,0)),"SID Match","No ST Match")) -> NYSSIS Match | U27: =IF(ISNUMBER(MATCH($D27,Disability!$B$2:$B$5962,0)),"SPED","Gen Ed") -> SPED
A28: Southside 291462 | B28: 46174 | C28: southside_291462_unified-roster.xlsx | D28: 4658757613 | F28: Titus | G28: Kaiden | H28: K | I28: 44196 | J28: Southside Academy Charter School | K28: 45903 | M28: 1 | N28: No Good | O28: ST states: enrolled at McKinley Brighton ES 7/3/25-9/8/25. With note that parent reported child will attend Southside. Need charter attendance report to change in ST. | P28: Gen Ed | Q28: =IFERROR(INDEX('ST Enroll Export'!$A$2:$A$3230,MATCH($D28,'ST Enroll Export'!$A$2:$A$3230,0)),IFERROR(IF(INDEX('ST Enroll Export'!$A$2:$A$3230,MATCH($E28,'ST Enroll Export'!$B$2:$B$3230,0))="","",INDEX('ST Enroll Export'!$A$2:$A$3230,MATCH($E28,'ST Enroll Export'!$B$2:$B$3230,0))),"Not Found")) -> Not Found | R28: =IFERROR(INDEX('ST Enroll Export'!$G$2:$G$3230,MATCH($D28,'ST Enroll Export'!$A$2:$A$3230,0)),IFERROR(INDEX('ST Enroll Export'!$G$2:$G$3230,MATCH($E28,'ST Enroll Export'!$B$2:$B$3230,0)),"Not Found")) -> Not Found | S28: =IFERROR(INDEX('ST Enroll Export'!$B$2:$B$3230,MATCH($D28,'ST Enroll Export'!$A$2:$A$3230,0)),IFERROR(INDEX('ST Enroll Export'!$B$2:$B$3230,MATCH($E28,'ST Enroll Export'!$B$2:$B$3230,0)),"Not Found")) -> Not Found | T28: =IF(ISNUMBER(MATCH($D28,'ST Enroll Export'!$A$2:$A$3230,0)),"NYSSIS Match",IF(ISNUMBER(MATCH($E28,'ST Enroll Export'!$B$2:$B$3230,0)),"SID Match","No ST Match")) -> No ST Match | U28: =IF(ISNUMBER(MATCH($D28,Disability!$B$2:$B$5962,0)),"SPED","Gen Ed") -> Gen Ed
A29: Southside 291462 | B29: 46174 | C29: southside_291462_unified-roster.xlsx | D29: 2808195416 | E29: 210017791 | F29: Maddox | G29: Kelani | H29: K | I29: 44152 | J29: Southside Academy Charter School | K29: 45917 | M29: 0.95 | N29: No Good | O29: ST states: student enrolled at Southside Academy Charter School 11/12/25- current. Entry date 3> day discrepancy. Need charter attendance record to change in ST. | P29: Gen Ed | Q29: =IFERROR(INDEX('ST Enroll Export'!$A$2:$A$3230,MATCH($D29,'ST Enroll Export'!$A$2:$A$3230,0)),IFERROR(IF(INDEX('ST Enroll Export'!$A$2:$A$3230,MATCH($E29,'ST Enroll Export'!$B$2:$B$3230,0))="","",INDEX('ST Enroll Export'!$A$2:$A$3230,MATCH($E29,'ST Enroll Export'!$B$2:$B$3230,0))),"Not Found")) -> 2808195416 | R29: =IFERROR(INDEX('ST Enroll Export'!$G$2:$G$3230,MATCH($D29,'ST Enroll Export'!$A$2:$A$3230,0)),IFERROR(INDEX('ST Enroll Export'!$G$2:$G$3230,MATCH($E29,'ST Enroll Export'!$B$2:$B$3230,0)),"Not Found")) -> Southside Academy Charter School | S29: =IFERROR(INDEX('ST Enroll Export'!$B$2:$B$3230,MATCH($D29,'ST Enroll Export'!$A$2:$A$3230,0)),IFERROR(INDEX('ST Enroll Export'!$B$2:$B$3230,MATCH($E29,'ST Enroll Export'!$B$2:$B$3230,0)),"Not Found")) -> 210017791 | T29: =IF(ISNUMBER(MATCH($D29,'ST Enroll Export'!$A$2:$A$3230,0)),"NYSSIS Match",IF(ISNUMBER(MATCH($E29,'ST Enroll Export'!$B$2:$B$3230,0)),"SID Match","No ST Match")) -> NYSSIS Match | U29: =IF(ISNUMBER(MATCH($D29,Disability!$B$2:$B$5962,0)),"SPED","Gen Ed") -> Gen Ed
A30: Southside 291462 | B30: 46174 | C30: southside_291462_unified-roster.xlsx | D30: 8014067546 | E30: 210022082 | F30: Suressi | G30: Kilani | H30: K | I30: 43979 | J30: Southside Academy Charter School | K30: 45905 | L30: 46010 | M30: 0.35 | N30: No Good | O30: ST states: student enrolled at Southside Academy Charter School 12/10/2025 - 12/21/2025. Entry date 3> day discrepancy. Need charter attendance record to change in ST. | P30: Gen Ed | Q30: =IFERROR(INDEX('ST Enroll Export'!$A$2:$A$3230,MATCH($D30,'ST Enroll Export'!$A$2:$A$3230,0)),IFERROR(IF(INDEX('ST Enroll Export'!$A$2:$A$3230,MATCH($E30,'ST Enroll Export'!$B$2:$B$3230,0))="","",INDEX('ST Enroll Export'!$A$2:$A$3230,MATCH($E30,'ST Enroll Export'!$B$2:$B$3230,0))),"Not Found")) -> 8014067546 | R30: =IFERROR(INDEX('ST Enroll Export'!$G$2:$G$3230,MATCH($D30,'ST Enroll Export'!$A$2:$A$3230,0)),IFERROR(INDEX('ST Enroll Export'!$G$2:$G$3230,MATCH($E30,'ST Enroll Export'!$B$2:$B$3230,0)),"Not Found")) -> Southside Academy Charter School | S30: =IFERROR(INDEX('ST Enroll Export'!$B$2:$B$3230,MATCH($D30,'ST Enroll Export'!$A$2:$A$3230,0)),IFERROR(INDEX('ST Enroll Export'!$B$2:$B$3230,MATCH($E30,'ST Enroll Export'!$B$2:$B$3230,0)),"Not Found")) -> 210022082 | T30: =IF(ISNUMBER(MATCH($D30,'ST Enroll Export'!$A$2:$A$3230,0)),"NYSSIS Match",IF(ISNUMBER(MATCH($E30,'ST Enroll Export'!$B$2:$B$3230,0)),"SID Match","No ST Match")) -> NYSSIS Match | U30: =IF(ISNUMBER(MATCH($D30,Disability!$B$2:$B$5962,0)),"SPED","Gen Ed") -> Gen Ed
